Workbook

Sheet DashBoard
A1: 0
D2: Img | R2: 2026 | T2: 🔴 | U2: -7 | V2: -6 | W2: -5 | X2: -4 | Y2: -3 | Z2: -2 | AA2: -1 | AB2: 0 | AC2: 1 | AD2: 2 | AE2: 3 | AF2: 4 | AG2: 5 | AH2: 6 | AI2: 7 | AJ2: 8 | AK2: 9 | AL2: 10 | AM2: 11 | AN2: 12 | AO2: 13 | AP2: 14 | AQ2: 15 | AR2: 16 | AS2: 17 | AT2: 18 | AU2: 19 | AV2: 20 | AW2: 21 | AX2: 22 | AY2: 23 | AZ2: 24 | BA2: 25 | BB2: 26 | BC2: 27 | BD2: 28 | BE2: 29 | BF2: 30 | BG2: 31 | BH2: 32 | BI2: 33 | BJ2: 34 | BK2: 35 | BL2: 36 | BM2: 37 | BN2: 38 | BO2: 39 | BP2: 40 | BQ2: 41 | BR2: 42 | BS2: 43 | BT2: 44 | BU2: 45 | BV2: 46 | BW2: 47 | BX2: 48 | BY2: 49 | BZ2: 50 | CA2: 51 | CB2: 52 | CC2: 53 | CD2: 54 | CE2: 55 | CF2: 56 | CG2: 57 | CH2: 58 | CI2: 59 | CJ2: 60 | CK2: 61 | CL2: 62 | CM2: 63 | CN2: 64 | CO2: 65 | CP2: 66 | CQ2: 67 | CR2: 68
A3: x | B3: =Summary!D29 -> VPA - 600 - Hieu | C3: Hieu.600 | D3: =iferror(vlookup(B3,StaffInformation!$F:$I,2,false),"") | E3: =iferror(vlookup(B3,Summary!$D:$V,19,false),) -> 0 | Q3: 1 | R3: Hieu.600 | T3: 0 | U3: =if(and($T3<0,$T3<=U$2),$A$2, ) | V3: =if(and($T3<0,$T3<=V$2),$A$2, ) | W3: =if(and($T3<0,$T3<=W$2),$A$2, ) | X3: =if(and($T3<0,$T3<=X$2),$A$2, ) | Y3: =if(and($T3<0,$T3<=Y$2),$A$2, ) | Z3: =if(and($T3<0,$T3<=Z$2),$A$2, ) | AA3: =if(and($T3<0,$T3<=AA$2),$A$2, ) | AB3: =if(T3=0,$A$3, ) -> x | AC3: =if(and(10>=$T3,$T3>=AC$2),$A$4,if(and(10<=$T3,$T3>=AC$2),$A$5, )) | AD3: =if(and(10>=$T3,$T3>=AD$2),$A$4,if(and(10<=$T3,$T3>=AD$2),$A$5, )) | AE3: =if(and(10>=$T3,$T3>=AE$2),$A$4,if(and(10<=$T3,$T3>=AE$2),$A$5, )) | AF3: =if(and(10>=$T3,$T3>=AF$2),$A$4,if(and(10<=$T3,$T3>=AF$2),$A$5, )) | AG3: =if(and(10>=$T3,$T3>=AG$2),$A$4,if(and(10<=$T3,$T3>=AG$2),$A$5, )) | AH3: =if(and(10>=$T3,$T3>=AH$2),$A$4,if(and(10<=$T3,$T3>=AH$2),$A$5, )) | AI3: =if(and(10>=$T3,$T3>=AI$2),$A$4,if(and(10<=$T3,$T3>=AI$2),$A$5, )) | AJ3: =if(and(10>=$T3,$T3>=AJ$2),$A$4,if(and(10<=$T3,$T3>=AJ$2),$A$5, )) | ... CR3: =if(and(10>=$T3,$T3>=CR$2),$A$4,if(and(10<=$T3,$T3>=CR$2),$A$5, ))
B4: =Summary!D30 -> VPA - 600 - Dat | C4: Dat.600 | D4: =iferror(vlookup(B4,StaffInformation!$F:$I,2,false),"") | E4: =iferror(vlookup(B4,Summary!$D:$V,19,false),) -> 0 | Q4: 2 | R4: Dat.600 | T4: 0 | U4: =if(and($T4<0,$T4<=U$2),$A$2, ) | V4: =if(and($T4<0,$T4<=V$2),$A$2, ) | W4: =if(and($T4<0,$T4<=W$2),$A$2, ) | X4: =if(and($T4<0,$T4<=X$2),$A$2, ) | Y4: =if(and($T4<0,$T4<=Y$2),$A$2, ) | Z4: =if(and($T4<0,$T4<=Z$2),$A$2, ) | AA4: =if(and($T4<0,$T4<=AA$2),$A$2, ) | AB4: =if(T4=0,$A$3, ) -> x | AC4: =if(and(10>=$T4,$T4>=AC$2),$A$4,if(and(10<=$T4,$T4>=AC$2),$A$5, )) | AD4: =if(and(10>=$T4,$T4>=AD$2),$A$4,if(and(10<=$T4,$T4>=AD$2),$A$5, )) | AE4: =if(and(10>=$T4,$T4>=AE$2),$A$4,if(and(10<=$T4,$T4>=AE$2),$A$5, )) | AF4: =if(and(10>=$T4,$T4>=AF$2),$A$4,if(and(10<=$T4,$T4>=AF$2),$A$5, )) | AG4: =if(and(10>=$T4,$T4>=AG$2),$A$4,if(and(10<=$T4,$T4>=AG$2),$A$5, )) | AH4: =if(and(10>=$T4,$T4>=AH$2),$A$4,if(and(10<=$T4,$T4>=AH$2),$A$5, )) | AI4: =if(and(10>=$T4,$T4>=AI$2),$A$4,if(and(10<=$T4,$T4>=AI$2),$A$5, )) | AJ4: =if(and(10>=$T4,$T4>=AJ$2),$A$4,if(and(10<=$T4,$T4>=AJ$2),$A$5, )) | ... CR4: =if(and(10>=$T4,$T4>=CR$2),$A$4,if(and(10<=$T4,$T4>=CR$2),$A$5, ))
B5: =Summary!D31 -> VPA - 600 - Trang | C5: Trang.600 | D5: =iferror(vlookup(B5,StaffInformation!$F:$I,2,false),"") | E5: =iferror(vlookup(B5,Summary!$D:$V,19,false),) -> 0 | G5: =IFERROR(__xludf.DUMMYFUNCTION("sort(filter(Q3:S26,Q3:Q26=1),1,false)"),1.0) -> 1 | H5: =IFERROR(__xludf.DUMMYFUNCTION("""COMPUTED_VALUE"""),"Hieu.600") -> Hieu.600 | I5: =IFERROR(__xludf.DUMMYFUNCTION("""COMPUTED_VALUE"""),"") | Q5: 3 | R5: Trang.600 | T5: 0 | U5: =if(and($T5<0,$T5<=U$2),$A$2, ) | V5: =if(and($T5<0,$T5<=V$2),$A$2, ) | W5: =if(and($T5<0,$T5<=W$2),$A$2, ) | X5: =if(and($T5<0,$T5<=X$2),$A$2, ) | Y5: =if(and($T5<0,$T5<=Y$2),$A$2, ) | Z5: =if(and($T5<0,$T5<=Z$2),$A$2, ) | AA5: =if(and($T5<0,$T5<=AA$2),$A$2, ) | AB5: =if(T5=0,$A$3, ) -> x | AC5: =if(and(10>=$T5,$T5>=AC$2),$A$4,if(and(10<=$T5,$T5>=AC$2),$A$5, )) | AD5: =if(and(10>=$T5,$T5>=AD$2),$A$4,if(and(10<=$T5,$T5>=AD$2),$A$5, )) | AE5: =if(and(10>=$T5,$T5>=AE$2),$A$4,if(and(10<=$T5,$T5>=AE$2),$A$5, )) | AF5: =if(and(10>=$T5,$T5>=AF$2),$A$4,if(and(10<=$T5,$T5>=AF$2),$A$5, )) | AG5: =if(and(10>=$T5,$T5>=AG$2),$A$4,if(and(10<=$T5,$T5>=AG$2),$A$5, )) | AH5: =if(and(10>=$T5,$T5>=AH$2),$A$4,if(and(10<=$T5,$T5>=AH$2),$A$5, )) | AI5: =if(and(10>=$T5,$T5>=AI$2),$A$4,if(and(10<=$T5,$T5>=AI$2),$A$5, )) | AJ5: =if(and(10>=$T5,$T5>=AJ$2),$A$4,if(and(10<=$T5,$T5>=AJ$2),$A$5, )) | ... CR5: =if(and(10>=$T5,$T5>=CR$2),$A$4,if(and(10<=$T5,$T5>=CR$2),$A$5, ))
B6: =Summary!D32 -> VPA - 600 - Duong | C6: Duong.600 | D6: =iferror(vlookup(B6,StaffInformation!$F:$I,2,false),"") | E6: =iferror(vlookup(B6,Summary!$D:$V,19,false),) -> 0 | Q6: 4 | R6: Duong.600 | T6: 0 | U6: =if(and($T6<0,$T6<=U$2),$A$2, ) | V6: =if(and($T6<0,$T6<=V$2),$A$2, ) | W6: =if(and($T6<0,$T6<=W$2),$A$2, ) | X6: =if(and($T6<0,$T6<=X$2),$A$2, ) | Y6: =if(and($T6<0,$T6<=Y$2),$A$2, ) | Z6: =if(and($T6<0,$T6<=Z$2),$A$2, ) | AA6: =if(and($T6<0,$T6<=AA$2),$A$2, ) | AB6: =if(T6=0,$A$3, ) -> x | AC6: =if(and(10>=$T6,$T6>=AC$2),$A$4,if(and(10<=$T6,$T6>=AC$2),$A$5, )) | AD6: =if(and(10>=$T6,$T6>=AD$2),$A$4,if(and(10<=$T6,$T6>=AD$2),$A$5, )) | AE6: =if(and(10>=$T6,$T6>=AE$2),$A$4,if(and(10<=$T6,$T6>=AE$2),$A$5, )) | AF6: =if(and(10>=$T6,$T6>=AF$2),$A$4,if(and(10<=$T6,$T6>=AF$2),$A$5, )) | AG6: =if(and(10>=$T6,$T6>=AG$2),$A$4,if(and(10<=$T6,$T6>=AG$2),$A$5, )) | AH6: =if(and(10>=$T6,$T6>=AH$2),$A$4,if(and(10<=$T6,$T6>=AH$2),$A$5, )) | AI6: =if(and(10>=$T6,$T6>=AI$2),$A$4,if(and(10<=$T6,$T6>=AI$2),$A$5, )) | AJ6: =if(and(10>=$T6,$T6>=AJ$2),$A$4,if(and(10<=$T6,$T6>=AJ$2),$A$5, )) | ... CR6: =if(and(10>=$T6,$T6>=CR$2),$A$4,if(and(10<=$T6,$T6>=CR$2),$A$5, ))
B7: =Summary!D33 -> VPA - 600 - Quynh | C7: Quynh.600 | D7: =iferror(vlookup(B7,'Copy of StaffInformation'!$F:$I,2,false),"") | E7: =iferror(vlookup(B7,Summary!$D:$V,19,false),) -> 0 | Q7: 5 | R7: Quynh.600 | T7: 0 | U7: =if(and($T7<0,$T7<=U$2),$A$2, ) | V7: =if(and($T7<0,$T7<=V$2),$A$2, ) | W7: =if(and($T7<0,$T7<=W$2),$A$2, ) | X7: =if(and($T7<0,$T7<=X$2),$A$2, ) | Y7: =if(and($T7<0,$T7<=Y$2),$A$2, ) | Z7: =if(and($T7<0,$T7<=Z$2),$A$2, ) | AA7: =if(and($T7<0,$T7<=AA$2),$A$2, ) | AB7: =if(T7=0,$A$3, ) -> x | AC7: =if(and(10>=$T7,$T7>=AC$2),$A$4,if(and(10<=$T7,$T7>=AC$2),$A$5, )) | AD7: =if(and(10>=$T7,$T7>=AD$2),$A$4,if(and(10<=$T7,$T7>=AD$2),$A$5, )) | AE7: =if(and(10>=$T7,$T7>=AE$2),$A$4,if(and(10<=$T7,$T7>=AE$2),$A$5, )) | AF7: =if(and(10>=$T7,$T7>=AF$2),$A$4,if(and(10<=$T7,$T7>=AF$2),$A$5, )) | AG7: =if(and(10>=$T7,$T7>=AG$2),$A$4,if(and(10<=$T7,$T7>=AG$2),$A$5, )) | AH7: =if(and(10>=$T7,$T7>=AH$2),$A$4,if(and(10<=$T7,$T7>=AH$2),$A$5, )) | AI7: =if(and(10>=$T7,$T7>=AI$2),$A$4,if(and(10<=$T7,$T7>=AI$2),$A$5, )) | AJ7: =if(and(10>=$T7,$T7>=AJ$2),$A$4,if(and(10<=$T7,$T7>=AJ$2),$A$5, )) | ... CR7: =if(and(10>=$T7,$T7>=CR$2),$A$4,if(and(10<=$T7,$T7>=CR$2),$A$5, ))
B8: =Summary!D34 -> VPA - 600 - Lam | C8: Lam.600 | D8: =iferror(vlookup(B8,StaffInformation!$F:$I,2,false),"") | E8: =iferror(vlookup(B8,Summary!$D:$V,19,false),) -> 0 | Q8: 6 | R8: Lam.600 | T8: 0 | U8: =if(and($T8<0,$T8<=U$2),$A$2, ) | V8: =if(and($T8<0,$T8<=V$2),$A$2, ) | W8: =if(and($T8<0,$T8<=W$2),$A$2, ) | X8: =if(and($T8<0,$T8<=X$2),$A$2, ) | Y8: =if(and($T8<0,$T8<=Y$2),$A$2, ) | Z8: =if(and($T8<0,$T8<=Z$2),$A$2, ) | AA8: =if(and($T8<0,$T8<=AA$2),$A$2, ) | AB8: =if(T8=0,$A$3, ) -> x | AC8: =if(and(10>=$T8,$T8>=AC$2),$A$4,if(and(10<=$T8,$T8>=AC$2),$A$5, )) | AD8: =if(and(10>=$T8,$T8>=AD$2),$A$4,if(and(10<=$T8,$T8>=AD$2),$A$5, )) | AE8: =if(and(10>=$T8,$T8>=AE$2),$A$4,if(and(10<=$T8,$T8>=AE$2),$A$5, )) | AF8: =if(and(10>=$T8,$T8>=AF$2),$A$4,if(and(10<=$T8,$T8>=AF$2),$A$5, )) | AG8: =if(and(10>=$T8,$T8>=AG$2),$A$4,if(and(10<=$T8,$T8>=AG$2),$A$5, )) | AH8: =if(and(10>=$T8,$T8>=AH$2),$A$4,if(and(10<=$T8,$T8>=AH$2),$A$5, )) | AI8: =if(and(10>=$T8,$T8>=AI$2),$A$4,if(and(10<=$T8,$T8>=AI$2),$A$5, )) | AJ8: =if(and(10>=$T8,$T8>=AJ$2),$A$4,if(and(10<=$T8,$T8>=AJ$2),$A$5, )) | ... CR8: =if(and(10>=$T8,$T8>=CR$2),$A$4,if(and(10<=$T8,$T8>=CR$2),$A$5, ))
B9: =Summary!D35 -> VPA - 600 - Huyen | C9: Huyen.600 | D9: =iferror(vlookup(B9,StaffInformation!$F:$I,2,false),"") | E9: =iferror(vlookup(B9,Summary!$D:$V,19,false),) -> 0 | Q9: 7 | R9: Huyen.600 | T9: 0 | U9: =if(and($T9<0,$T9<=U$2),$A$2, ) | V9: =if(and($T9<0,$T9<=V$2),$A$2, ) | W9: =if(and($T9<0,$T9<=W$2),$A$2, ) | X9: =if(and($T9<0,$T9<=X$2),$A$2, ) | Y9: =if(and($T9<0,$T9<=Y$2),$A$2, ) | Z9: =if(and($T9<0,$T9<=Z$2),$A$2, ) | AA9: =if(and($T9<0,$T9<=AA$2),$A$2, ) | AB9: =if(T9=0,$A$3, ) -> x | AC9: =if(and(10>=$T9,$T9>=AC$2),$A$4,if(and(10<=$T9,$T9>=AC$2),$A$5, )) | AD9: =if(and(10>=$T9,$T9>=AD$2),$A$4,if(and(10<=$T9,$T9>=AD$2),$A$5, )) | AE9: =if(and(10>=$T9,$T9>=AE$2),$A$4,if(and(10<=$T9,$T9>=AE$2),$A$5, )) | AF9: =if(and(10>=$T9,$T9>=AF$2),$A$4,if(and(10<=$T9,$T9>=AF$2),$A$5, )) | AG9: =if(and(10>=$T9,$T9>=AG$2),$A$4,if(and(10<=$T9,$T9>=AG$2),$A$5, )) | AH9: =if(and(10>=$T9,$T9>=AH$2),$A$4,if(and(10<=$T9,$T9>=AH$2),$A$5, )) | AI9: =if(and(10>=$T9,$T9>=AI$2),$A$4,if(and(10<=$T9,$T9>=AI$2),$A$5, )) | AJ9: =if(and(10>=$T9,$T9>=AJ$2),$A$4,if(and(10<=$T9,$T9>=AJ$2),$A$5, )) | ... CR9: =if(and(10>=$T9,$T9>=CR$2),$A$4,if(and(10<=$T9,$T9>=CR$2),$A$5, ))
B10: =Summary!D36 -> VPA - 600 - Quan | C10: Quan.600 | D10: =iferror(vlookup(B10,StaffInformation!$F:$I,2,false),"") | E10: =iferror(vlookup(B10,Summary!$D:$V,19,false),) -> 0 | Q10: 8 | R10: Quan.600 | T10: 0 | U10: =if(and($T10<0,$T10<=U$2),$A$2, ) | V10: =if(and($T10<0,$T10<=V$2),$A$2, ) | W10: =if(and($T10<0,$T10<=W$2),$A$2, ) | X10: =if(and($T10<0,$T10<=X$2),$A$2, ) | Y10: =if(and($T10<0,$T10<=Y$2),$A$2, ) | Z10: =if(and($T10<0,$T10<=Z$2),$A$2, ) | AA10: =if(and($T10<0,$T10<=AA$2),$A$2, ) | AB10: =if(T10=0,$A$3, ) -> x | AC10: =if(and(10>=$T10,$T10>=AC$2),$A$4,if(and(10<=$T10,$T10>=AC$2),$A$5, )) | AD10: =if(and(10>=$T10,$T10>=AD$2),$A$4,if(and(10<=$T10,$T10>=AD$2),$A$5, )) | AE10: =if(and(10>=$T10,$T10>=AE$2),$A$4,if(and(10<=$T10,$T10>=AE$2),$A$5, )) | AF10: =if(and(10>=$T10,$T10>=AF$2),$A$4,if(and(10<=$T10,$T10>=AF$2),$A$5, )) | AG10: =if(and(10>=$T10,$T10>=AG$2),$A$4,if(and(10<=$T10,$T10>=AG$2),$A$5, )) | AH10: =if(and(10>=$T10,$T10>=AH$2),$A$4,if(and(10<=$T10,$T10>=AH$2),$A$5, )) | AI10: =if(and(10>=$T10,$T10>=AI$2),$A$4,if(and(10<=$T10,$T10>=AI$2),$A$5, )) | AJ10: =if(and(10>=$T10,$T10>=AJ$2),$A$4,if(and(10<=$T10,$T10>=AJ$2),$A$5, )) | ... CR10: =if(and(10>=$T10,$T10>=CR$2),$A$4,if(and(10<=$T10,$T10>=CR$2),$A$5, ))
B11: =Summary!D37 -> VPA - 500 - Giang | C11: Giang.500 | D11: =iferror(vlookup(B11,'Copy of StaffInformation'!$F:$I,2,false),"") | E11: =iferror(vlookup(B11,Summary!$D:$V,19,false),) -> 0 | Q11: 9 | R11: Giang.500 | T11: 0 | U11: =if(and($T11<0,$T11<=U$2),$A$2, ) | V11: =if(and($T11<0,$T11<=V$2),$A$2, ) | W11: =if(and($T11<0,$T11<=W$2),$A$2, ) | X11: =if(and($T11<0,$T11<=X$2),$A$2, ) | Y11: =if(and($T11<0,$T11<=Y$2),$A$2, ) | Z11: =if(and($T11<0,$T11<=Z$2),$A$2, ) | AA11: =if(and($T11<0,$T11<=AA$2),$A$2, ) | AB11: =if(T11=0,$A$3, ) -> x | AC11: =if(and(10>=$T11,$T11>=AC$2),$A$4,if(and(10<=$T11,$T11>=AC$2),$A$5, )) | AD11: =if(and(10>=$T11,$T11>=AD$2),$A$4,if(and(10<=$T11,$T11>=AD$2),$A$5, )) | AE11: =if(and(10>=$T11,$T11>=AE$2),$A$4,if(and(10<=$T11,$T11>=AE$2),$A$5, )) | AF11: =if(and(10>=$T11,$T11>=AF$2),$A$4,if(and(10<=$T11,$T11>=AF$2),$A$5, )) | AG11: =if(and(10>=$T11,$T11>=AG$2),$A$4,if(and(10<=$T11,$T11>=AG$2),$A$5, )) | AH11: =if(and(10>=$T11,$T11>=AH$2),$A$4,if(and(10<=$T11,$T11>=AH$2),$A$5, )) | AI11: =if(and(10>=$T11,$T11>=AI$2),$A$4,if(and(10<=$T11,$T11>=AI$2),$A$5, )) | AJ11: =if(and(10>=$T11,$T11>=AJ$2),$A$4,if(and(10<=$T11,$T11>=AJ$2),$A$5, )) | ... CR11: =if(and(10>=$T11,$T11>=CR$2),$A$4,if(and(10<=$T11,$T11>=CR$2),$A$5, ))
B12: =Summary!D38 -> VPA - Vice Director - Lan Huong | C12: Lan Huong.600 | D12: =iferror(vlookup(B12,StaffInformation!$F:$I,2,false),"") | E12: =iferror(vlookup(B12,Summary!$D:$V,19,false),) -> 0 | G12: Hieu.600 | L12: =vlookup("Full Name:"&$G$12,StaffInformation!$C$6:$F$1153,4,false) -> Bui Trung Hieu | Q12: 10 | R12: Lan Huong.600 | T12: 0 | U12: =if(and($T12<0,$T12<=U$2),$A$2, ) | V12: =if(and($T12<0,$T12<=V$2),$A$2, ) | W12: =if(and($T12<0,$T12<=W$2),$A$2, ) | X12: =if(and($T12<0,$T12<=X$2),$A$2, ) | Y12: =if(and($T12<0,$T12<=Y$2),$A$2, ) | Z12: =if(and($T12<0,$T12<=Z$2),$A$2, ) | AA12: =if(and($T12<0,$T12<=AA$2),$A$2, ) | AB12: =if(T12=0,$A$3, ) -> x | AC12: =if(and(10>=$T12,$T12>=AC$2),$A$4,if(and(10<=$T12,$T12>=AC$2),$A$5, )) | AD12: =if(and(10>=$T12,$T12>=AD$2),$A$4,if(and(10<=$T12,$T12>=AD$2),$A$5, )) | AE12: =if(and(10>=$T12,$T12>=AE$2),$A$4,if(and(10<=$T12,$T12>=AE$2),$A$5, )) | AF12: =if(and(10>=$T12,$T12>=AF$2),$A$4,if(and(10<=$T12,$T12>=AF$2),$A$5, )) | AG12: =if(and(10>=$T12,$T12>=AG$2),$A$4,if(and(10<=$T12,$T12>=AG$2),$A$5, )) | AH12: =if(and(10>=$T12,$T12>=AH$2),$A$4,if(and(10<=$T12,$T12>=AH$2),$A$5, )) | AI12: =if(and(10>=$T12,$T12>=AI$2),$A$4,if(and(10<=$T12,$T12>=AI$2),$A$5, )) | AJ12: =if(and(10>=$T12,$T12>=AJ$2),$A$4,if(and(10<=$T12,$T12>=AJ$2),$A$5, )) | ... CR12: =if(and(10>=$T12,$T12>=CR$2),$A$4,if(and(10<=$T12,$T12>=CR$2),$A$5, ))
B13: =Summary!D39 -> TYM - 600 - Kien | C13: Kien.TYM | D13: =iferror(vlookup(B13,StaffInformation!$F:$I,2,false),"") | E13: =iferror(vlookup(B13,Summary!$D:$V,19,false),) -> 0 | Q13: 11 | R13: Kien.TYM | T13: 0 | U13: =if(and($T13<0,$T13<=U$2),$A$2, ) | V13: =if(and($T13<0,$T13<=V$2),$A$2, ) | W13: =if(and($T13<0,$T13<=W$2),$A$2, ) | X13: =if(and($T13<0,$T13<=X$2),$A$2, ) | Y13: =if(and($T13<0,$T13<=Y$2),$A$2, ) | Z13: =if(and($T13<0,$T13<=Z$2),$A$2, ) | AA13: =if(and($T13<0,$T13<=AA$2),$A$2, ) | AB13: =if(T13=0,$A$3, ) -> x | AC13: =if(and(10>=$T13,$T13>=AC$2),$A$4,if(and(10<=$T13,$T13>=AC$2),$A$5, )) | AD13: =if(and(10>=$T13,$T13>=AD$2),$A$4,if(and(10<=$T13,$T13>=AD$2),$A$5, )) | AE13: =if(and(10>=$T13,$T13>=AE$2),$A$4,if(and(10<=$T13,$T13>=AE$2),$A$5, )) | AF13: =if(and(10>=$T13,$T13>=AF$2),$A$4,if(and(10<=$T13,$T13>=AF$2),$A$5, )) | AG13: =if(and(10>=$T13,$T13>=AG$2),$A$4,if(and(10<=$T13,$T13>=AG$2),$A$5, )) | AH13: =if(and(10>=$T13,$T13>=AH$2),$A$4,if(and(10<=$T13,$T13>=AH$2),$A$5, )) | AI13: =if(and(10>=$T13,$T13>=AI$2),$A$4,if(and(10<=$T13,$T13>=AI$2),$A$5, )) | AJ13: =if(and(10>=$T13,$T13>=AJ$2),$A$4,if(and(10<=$T13,$T13>=AJ$2),$A$5, )) | ... CR13: =if(and(10>=$T13,$T13>=CR$2),$A$4,if(and(10<=$T13,$T13>=CR$2),$A$5, ))
B14: =Summary!D40 -> VPA - 600 - Vu | C14: Vu.600 | D14: =iferror(vlookup(B14,StaffInformation!$F:$I,2,false),"") | E14: =iferror(vlookup(B14,Summary!$D:$V,19,false),) -> 0 | G14: Hieu.600 | L14: =vlookup("Position:"&$G$12,StaffInformation!$C$6:$F$1153,4,false) -> Designer | Q14: 12 | R14: Vu.600 | T14: 0 | U14: =if(and($T14<0,$T14<=U$2),$A$2, ) | V14: =if(and($T14<0,$T14<=V$2),$A$2, ) | W14: =if(and($T14<0,$T14<=W$2),$A$2, ) | X14: =if(and($T14<0,$T14<=X$2),$A$2, ) | Y14: =if(and($T14<0,$T14<=Y$2),$A$2, ) | Z14: =if(and($T14<0,$T14<=Z$2),$A$2, ) | AA14: =if(and($T14<0,$T14<=AA$2),$A$2, ) | AB14: =if(T14=0,$A$3, ) -> x | AC14: =if(and(10>=$T14,$T14>=AC$2),$A$4,if(and(10<=$T14,$T14>=AC$2),$A$5, )) | AD14: =if(and(10>=$T14,$T14>=AD$2),$A$4,if(and(10<=$T14,$T14>=AD$2),$A$5, )) | AE14: =if(and(10>=$T14,$T14>=AE$2),$A$4,if(and(10<=$T14,$T14>=AE$2),$A$5, )) | AF14: =if(and(10>=$T14,$T14>=AF$2),$A$4,if(and(10<=$T14,$T14>=AF$2),$A$5, )) | AG14: =if(and(10>=$T14,$T14>=AG$2),$A$4,if(and(10<=$T14,$T14>=AG$2),$A$5, )) | AH14: =if(and(10>=$T14,$T14>=AH$2),$A$4,if(and(10<=$T14,$T14>=AH$2),$A$5, )) | AI14: =if(and(10>=$T14,$T14>=AI$2),$A$4,if(and(10<=$T14,$T14>=AI$2),$A$5, )) | AJ14: =if(and(10>=$T14,$T14>=AJ$2),$A$4,if(and(10<=$T14,$T14>=AJ$2),$A$5, )) | ... CR14: =if(and(10>=$T14,$T14>=CR$2),$A$4,if(and(10<=$T14,$T14>=CR$2),$A$5, ))
B15: =Summary!D41 -> ADD - 600 - Quyet | C15: Quyet.600 | D15: =iferror(vlookup(B15,'Copy of StaffInformation'!$F:$I,2,false),"") | E15: =iferror(vlookup(B15,Summary!$D:$V,19,false),) -> 0 | Q15: 13 | R15: Quyet.600 | T15: 0 | U15: =if(and($T15<0,$T15<=U$2),$A$2, ) | V15: =if(and($T15<0,$T15<=V$2),$A$2, ) | W15: =if(and($T15<0,$T15<=W$2),$A$2, ) | X15: =if(and($T15<0,$T15<=X$2),$A$2, ) | Y15: =if(and($T15<0,$T15<=Y$2),$A$2, ) | Z15: =if(and($T15<0,$T15<=Z$2),$A$2, ) | AA15: =if(and($T15<0,$T15<=AA$2),$A$2, ) | AB15: =if(T15=0,$A$3, ) -> x | AC15: =if(and(10>=$T15,$T15>=AC$2),$A$4,if(and(10<=$T15,$T15>=AC$2),$A$5, )) | AD15: =if(and(10>=$T15,$T15>=AD$2),$A$4,if(and(10<=$T15,$T15>=AD$2),$A$5, )) | AE15: =if(and(10>=$T15,$T15>=AE$2),$A$4,if(and(10<=$T15,$T15>=AE$2),$A$5, )) | AF15: =if(and(10>=$T15,$T15>=AF$2),$A$4,if(and(10<=$T15,$T15>=AF$2),$A$5, )) | AG15: =if(and(10>=$T15,$T15>=AG$2),$A$4,if(and(10<=$T15,$T15>=AG$2),$A$5, )) | AH15: =if(and(10>=$T15,$T15>=AH$2),$A$4,if(and(10<=$T15,$T15>=AH$2),$A$5, )) | AI15: =if(and(10>=$T15,$T15>=AI$2),$A$4,if(and(10<=$T15,$T15>=AI$2),$A$5, )) | AJ15: =if(and(10>=$T15,$T15>=AJ$2),$A$4,if(and(10<=$T15,$T15>=AJ$2),$A$5, )) | ... CR15: =if(and(10>=$T15,$T15>=CR$2),$A$4,if(and(10<=$T15,$T15>=CR$2),$A$5, ))
B16: =Summary!D42 -> ADC - Site Manager - Thuyet | C16: Thuyet.Site | D16: =iferror(vlookup(B16,StaffInformation!$F:$I,2,false),"") | E16: =iferror(vlookup(B16,Summary!$D:$V,19,false),) -> 0 | G16: Hieu.600 | L16: =vlookup("Birth:"&$G$12,StaffInformation!$C$6:$F$1153,4,false) -> 34465 | Q16: 14 | R16: Thuyet.Site | T16: 0 | U16: =if(and($T16<0,$T16<=U$2),$A$2, ) | V16: =if(and($T16<0,$T16<=V$2),$A$2, ) | W16: =if(and($T16<0,$T16<=W$2),$A$2, ) | X16: =if(and($T16<0,$T16<=X$2),$A$2, ) | Y16: =if(and($T16<0,$T16<=Y$2),$A$2, ) | Z16: =if(and($T16<0,$T16<=Z$2),$A$2, ) | AA16: =if(and($T16<0,$T16<=AA$2),$A$2, ) | AB16: =if(T16=0,$A$3, ) -> x | AC16: =if(and(10>=$T16,$T16>=AC$2),$A$4,if(and(10<=$T16,$T16>=AC$2),$A$5, )) | AD16: =if(and(10>=$T16,$T16>=AD$2),$A$4,if(and(10<=$T16,$T16>=AD$2),$A$5, )) | AE16: =if(and(10>=$T16,$T16>=AE$2),$A$4,if(and(10<=$T16,$T16>=AE$2),$A$5, )) | AF16: =if(and(10>=$T16,$T16>=AF$2),$A$4,if(and(10<=$T16,$T16>=AF$2),$A$5, )) | AG16: =if(and(10>=$T16,$T16>=AG$2),$A$4,if(and(10<=$T16,$T16>=AG$2),$A$5, )) | AH16: =if(and(10>=$T16,$T16>=AH$2),$A$4,if(and(10<=$T16,$T16>=AH$2),$A$5, )) | AI16: =if(and(10>=$T16,$T16>=AI$2),$A$4,if(and(10<=$T16,$T16>=AI$2),$A$5, )) | AJ16: =if(and(10>=$T16,$T16>=AJ$2),$A$4,if(and(10<=$T16,$T16>=AJ$2),$A$5, )) | ... CR16: =if(and(10>=$T16,$T16>=CR$2),$A$4,if(and(10<=$T16,$T16>=CR$2),$A$5, ))
B17: =Summary!D44 | C17: =iferror(vlookup(B17,Summary!$D:$E,2,false),) | D17: =iferror(vlookup(B17,StaffInformation!$F:$I,2,false),"") | E17: =iferror(vlookup(B17,Summary!$D:$V,19,false),) | Q17: 15 | R17: Tien.200 | T17: 0 | U17: =if(and($T17<0,$T17<=U$2),$A$2, ) | V17: =if(and($T17<0,$T17<=V$2),$A$2, ) | W17: =if(and($T17<0,$T17<=W$2),$A$2, ) | X17: =if(and($T17<0,$T17<=X$2),$A$2, ) | Y17: =if(and($T17<0,$T17<=Y$2),$A$2, ) | Z17: =if(and($T17<0,$T17<=Z$2),$A$2, ) | AA17: =if(and($T17<0,$T17<=AA$2),$A$2, ) | AB17: =if(T17=0,$A$3, ) -> x | AC17: =if(and(10>=$T17,$T17>=AC$2),$A$4,if(and(10<=$T17,$T17>=AC$2),$A$5, )) | AD17: =if(and(10>=$T17,$T17>=AD$2),$A$4,if(and(10<=$T17,$T17>=AD$2),$A$5, )) | AE17: =if(and(10>=$T17,$T17>=AE$2),$A$4,if(and(10<=$T17,$T17>=AE$2),$A$5, )) | AF17: =if(and(10>=$T17,$T17>=AF$2),$A$4,if(and(10<=$T17,$T17>=AF$2),$A$5, )) | AG17: =if(and(10>=$T17,$T17>=AG$2),$A$4,if(and(10<=$T17,$T17>=AG$2),$A$5, )) | AH17: =if(and(10>=$T17,$T17>=AH$2),$A$4,if(and(10<=$T17,$T17>=AH$2),$A$5, )) | AI17: =if(and(10>=$T17,$T17>=AI$2),$A$4,if(and(10<=$T17,$T17>=AI$2),$A$5, )) | AJ17: =if(and(10>=$T17,$T17>=AJ$2),$A$4,if(and(10<=$T17,$T17>=AJ$2),$A$5, )) | ... CR17: =if(and(10>=$T17,$T17>=CR$2),$A$4,if(and(10<=$T17,$T17>=CR$2),$A$5, ))
B18: =Summary!D45 -> GROUP - 200 - Tien | C18: Tien.200 | D18: =iferror(vlookup(B18,StaffInformation!$F:$I,2,false),"") | E18: =iferror(vlookup(B18,Summary!$D:$V,19,false),) -> 0 | G18: Hieu.600 | L18: =vlookup("Experience:"&$G$12,StaffInformation!$C$6:$F$1153,4,false) -> 8 years | Q18: 16 | R18: Luat.000 | T18: 0 | U18: =if(and($T18<0,$T18<=U$2),$A$2, ) | V18: =if(and($T18<0,$T18<=V$2),$A$2, ) | W18: =if(and($T18<0,$T18<=W$2),$A$2, ) | X18: =if(and($T18<0,$T18<=X$2),$A$2, ) | Y18: =if(and($T18<0,$T18<=Y$2),$A$2, ) | Z18: =if(and($T18<0,$T18<=Z$2),$A$2, ) | AA18: =if(and($T18<0,$T18<=AA$2),$A$2, ) | AB18: =if(T18=0,$A$3, ) -> x | AC18: =if(and(10>=$T18,$T18>=AC$2),$A$4,if(and(10<=$T18,$T18>=AC$2),$A$5, )) | AD18: =if(and(10>=$T18,$T18>=AD$2),$A$4,if(and(10<=$T18,$T18>=AD$2),$A$5, )) | AE18: =if(and(10>=$T18,$T18>=AE$2),$A$4,if(and(10<=$T18,$T18>=AE$2),$A$5, )) | AF18: =if(and(10>=$T18,$T18>=AF$2),$A$4,if(and(10<=$T18,$T18>=AF$2),$A$5, )) | AG18: =if(and(10>=$T18,$T18>=AG$2),$A$4,if(and(10<=$T18,$T18>=AG$2),$A$5, )) | AH18: =if(and(10>=$T18,$T18>=AH$2),$A$4,if(and(10<=$T18,$T18>=AH$2),$A$5, )) | AI18: =if(and(10>=$T18,$T18>=AI$2),$A$4,if(and(10<=$T18,$T18>=AI$2),$A$5, )) | AJ18: =if(and(10>=$T18,$T18>=AJ$2),$A$4,if(and(10<=$T18,$T18>=AJ$2),$A$5, )) | ... CR18: =if(and(10>=$T18,$T18>=CR$2),$A$4,if(and(10<=$T18,$T18>=CR$2),$A$5, ))
B19: =Summary!D46 -> GROUP - 000-200 - Luat | C19: Luat.000 | D19: =iferror(vlookup(B19,StaffInformation!$F:$I,2,false),"") | E19: =iferror(vlookup(B19,Summary!$D:$V,19,false),) -> 0 | Q19: 17 | R19: Duy Anh.200 | T19: 0 | U19: =if(and($T19<0,$T19<=U$2),$A$2, ) | V19: =if(and($T19<0,$T19<=V$2),$A$2, ) | W19: =if(and($T19<0,$T19<=W$2),$A$2, ) | X19: =if(and($T19<0,$T19<=X$2),$A$2, ) | Y19: =if(and($T19<0,$T19<=Y$2),$A$2, ) | Z19: =if(and($T19<0,$T19<=Z$2),$A$2, ) | AA19: =if(and($T19<0,$T19<=AA$2),$A$2, ) | AB19: =if(T19=0,$A$3, ) -> x | AC19: =if(and(10>=$T19,$T19>=AC$2),$A$4,if(and(10<=$T19,$T19>=AC$2),$A$5, )) | AD19: =if(and(10>=$T19,$T19>=AD$2),$A$4,if(and(10<=$T19,$T19>=AD$2),$A$5, )) | AE19: =if(and(10>=$T19,$T19>=AE$2),$A$4,if(and(10<=$T19,$T19>=AE$2),$A$5, )) | AF19: =if(and(10>=$T19,$T19>=AF$2),$A$4,if(and(10<=$T19,$T19>=AF$2),$A$5, )) | AG19: =if(and(10>=$T19,$T19>=AG$2),$A$4,if(and(10<=$T19,$T19>=AG$2),$A$5, )) | AH19: =if(and(10>=$T19,$T19>=AH$2),$A$4,if(and(10<=$T19,$T19>=AH$2),$A$5, )) | AI19: =if(and(10>=$T19,$T19>=AI$2),$A$4,if(and(10<=$T19,$T19>=AI$2),$A$5, )) | AJ19: =if(and(10>=$T19,$T19>=AJ$2),$A$4,if(and(10<=$T19,$T19>=AJ$2),$A$5, )) | ... CR19: =if(and(10>=$T19,$T19>=CR$2),$A$4,if(and(10<=$T19,$T19>=CR$2),$A$5, ))
B20: =Summary!D47 -> GROUP - 200 - Duy Anh | C20: Duy Anh.200 | D20: =iferror(vlookup(B20,StaffInformation!$F:$I,2,false),"") | E20: =iferror(vlookup(B20,Summary!$D:$V,19,false),) -> 0 | G20: Hieu.600 | L20: =vlookup("Quote:"&$G$12,StaffInformation!$C$6:$F$1153,4,false) -> Bringing the forest into the city | Q20: 18 | R20: Trang.300 | T20: 0 | U20: =if(and($T20<0,$T20<=U$2),$A$2, ) | V20: =if(and($T20<0,$T20<=V$2),$A$2, ) | W20: =if(and($T20<0,$T20<=W$2),$A$2, ) | X20: =if(and($T20<0,$T20<=X$2),$A$2, ) | Y20: =if(and($T20<0,$T20<=Y$2),$A$2, ) | Z20: =if(and($T20<0,$T20<=Z$2),$A$2, ) | AA20: =if(and($T20<0,$T20<=AA$2),$A$2, ) | AB20: =if(T20=0,$A$3, ) -> x | AC20: =if(and(10>=$T20,$T20>=AC$2),$A$4,if(and(10<=$T20,$T20>=AC$2),$A$5, )) | AD20: =if(and(10>=$T20,$T20>=AD$2),$A$4,if(and(10<=$T20,$T20>=AD$2),$A$5, )) | AE20: =if(and(10>=$T20,$T20>=AE$2),$A$4,if(and(10<=$T20,$T20>=AE$2),$A$5, )) | AF20: =if(and(10>=$T20,$T20>=AF$2),$A$4,if(and(10<=$T20,$T20>=AF$2),$A$5, )) | AG20: =if(and(10>=$T20,$T20>=AG$2),$A$4,if(and(10<=$T20,$T20>=AG$2),$A$5, )) | AH20: =if(and(10>=$T20,$T20>=AH$2),$A$4,if(and(10<=$T20,$T20>=AH$2),$A$5, )) | AI20: =if(and(10>=$T20,$T20>=AI$2),$A$4,if(and(10<=$T20,$T20>=AI$2),$A$5, )) | AJ20: =if(and(10>=$T20,$T20>=AJ$2),$A$4,if(and(10<=$T20,$T20>=AJ$2),$A$5, )) | ... CR20: =if(and(10>=$T20,$T20>=CR$2),$A$4,if(and(10<=$T20,$T20>=CR$2),$A$5, ))
B21: =Summary!D48 -> GROUP - 300 - Trang | C21: Trang.300 | D21: =iferror(vlookup(B21,StaffInformation!$F:$I,2,false),"") | E21: =iferror(vlookup(B21,Summary!$D:$V,19,false),) -> 0 | F21: 1 | G21: Hieu.600 | Q21: 19 | R21: Sim.300 | T21: 0 | U21: =if(and($T21<0,$T21<=U$2),$A$2, ) | V21: =if(and($T21<0,$T21<=V$2),$A$2, ) | W21: =if(and($T21<0,$T21<=W$2),$A$2, ) | X21: =if(and($T21<0,$T21<=X$2),$A$2, ) | Y21: =if(and($T21<0,$T21<=Y$2),$A$2, ) | Z21: =if(and($T21<0,$T21<=Z$2),$A$2, ) | AA21: =if(and($T21<0,$T21<=AA$2),$A$2, ) | AB21: =if(T21=0,$A$3, ) -> x | AC21: =if(and(10>=$T21,$T21>=AC$2),$A$4,if(and(10<=$T21,$T21>=AC$2),$A$5, )) | AD21: =if(and(10>=$T21,$T21>=AD$2),$A$4,if(and(10<=$T21,$T21>=AD$2),$A$5, )) | AE21: =if(and(10>=$T21,$T21>=AE$2),$A$4,if(and(10<=$T21,$T21>=AE$2),$A$5, )) | AF21: =if(and(10>=$T21,$T21>=AF$2),$A$4,if(and(10<=$T21,$T21>=AF$2),$A$5, )) | AG21: =if(and(10>=$T21,$T21>=AG$2),$A$4,if(and(10<=$T21,$T21>=AG$2),$A$5, )) | AH21: =if(and(10>=$T21,$T21>=AH$2),$A$4,if(and(10<=$T21,$T21>=AH$2),$A$5, )) | AI21: =if(and(10>=$T21,$T21>=AI$2),$A$4,if(and(10<=$T21,$T21>=AI$2),$A$5, )) | AJ21: =if(and(10>=$T21,$T21>=AJ$2),$A$4,if(and(10<=$T21,$T21>=AJ$2),$A$5, )) | ... CR21: =if(and(10>=$T21,$T21>=CR$2),$A$4,if(and(10<=$T21,$T21>=CR$2),$A$5, ))
B22: =Summary!D49 -> GROUP - 300 - Sim | C22: Sim.300 | D22: =iferror(vlookup(B22,StaffInformation!$F:$I,2,false),"") | E22: =iferror(vlookup(B22,Summary!$D:$V,19,false),) -> 0 | F22: 2 | Q22: 20 | R22: Thuy.300 | T22: 0 | U22: =if(and($T22<0,$T22<=U$2),$A$2, ) | V22: =if(and($T22<0,$T22<=V$2),$A$2, ) | W22: =if(and($T22<0,$T22<=W$2),$A$2, ) | X22: =if(and($T22<0,$T22<=X$2),$A$2, ) | Y22: =if(and($T22<0,$T22<=Y$2),$A$2, ) | Z22: =if(and($T22<0,$T22<=Z$2),$A$2, ) | AA22: =if(and($T22<0,$T22<=AA$2),$A$2, ) | AB22: =if(T22=0,$A$3, ) -> x | AC22: =if(and(10>=$T22,$T22>=AC$2),$A$4,if(and(10<=$T22,$T22>=AC$2),$A$5, )) | AD22: =if(and(10>=$T22,$T22>=AD$2),$A$4,if(and(10<=$T22,$T22>=AD$2),$A$5, )) | AE22: =if(and(10>=$T22,$T22>=AE$2),$A$4,if(and(10<=$T22,$T22>=AE$2),$A$5, )) | AF22: =if(and(10>=$T22,$T22>=AF$2),$A$4,if(and(10<=$T22,$T22>=AF$2),$A$5, )) | AG22: =if(and(10>=$T22,$T22>=AG$2),$A$4,if(and(10<=$T22,$T22>=AG$2),$A$5, )) | AH22: =if(and(10>=$T22,$T22>=AH$2),$A$4,if(and(10<=$T22,$T22>=AH$2),$A$5, )) | AI22: =if(and(10>=$T22,$T22>=AI$2),$A$4,if(and(10<=$T22,$T22>=AI$2),$A$5, )) | AJ22: =if(and(10>=$T22,$T22>=AJ$2),$A$4,if(and(10<=$T22,$T22>=AJ$2),$A$5, )) | ... CR22: =if(and(10>=$T22,$T22>=CR$2),$A$4,if(and(10<=$T22,$T22>=CR$2),$A$5, ))
B23: =Summary!D50 -> GROUP - 300 - Thuy | C23: Thuy.300 | D23: =iferror(vlookup(B23,StaffInformation!$F:$I,2,false),"") | E23: =iferror(vlookup(B23,Summary!$D:$V,19,false),) -> 0 | F23: 3 | G23: Hieu.600 | Q23: 21 | R23: Hong.300 | T23: 0 | U23: =if(and($T23<0,$T23<=U$2),$A$2, ) | V23: =if(and($T23<0,$T23<=V$2),$A$2, ) | W23: =if(and($T23<0,$T23<=W$2),$A$2, ) | X23: =if(and($T23<0,$T23<=X$2),$A$2, ) | Y23: =if(and($T23<0,$T23<=Y$2),$A$2, ) | Z23: =if(and($T23<0,$T23<=Z$2),$A$2, ) | AA23: =if(and($T23<0,$T23<=AA$2),$A$2, ) | AB23: =if(T23=0,$A$3, ) -> x | AC23: =if(and(10>=$T23,$T23>=AC$2),$A$4,if(and(10<=$T23,$T23>=AC$2),$A$5, )) | AD23: =if(and(10>=$T23,$T23>=AD$2),$A$4,if(and(10<=$T23,$T23>=AD$2),$A$5, )) | AE23: =if(and(10>=$T23,$T23>=AE$2),$A$4,if(and(10<=$T23,$T23>=AE$2),$A$5, )) | AF23: =if(and(10>=$T23,$T23>=AF$2),$A$4,if(and(10<=$T23,$T23>=AF$2),$A$5, )) | AG23: =if(and(10>=$T23,$T23>=AG$2),$A$4,if(and(10<=$T23,$T23>=AG$2),$A$5, )) | AH23: =if(and(10>=$T23,$T23>=AH$2),$A$4,if(and(10<=$T23,$T23>=AH$2),$A$5, )) | AI23: =if(and(10>=$T23,$T23>=AI$2),$A$4,if(and(10<=$T23,$T23>=AI$2),$A$5, )) | AJ23: =if(and(10>=$T23,$T23>=AJ$2),$A$4,if(and(10<=$T23,$T23>=AJ$2),$A$5, )) | ... CR23: =if(and(10>=$T23,$T23>=CR$2),$A$4,if(and(10<=$T23,$T23>=CR$2),$A$5, ))
B24: =Summary!D51 -> GROUP - 300 - Hong | C24: Hong.300 | D24: =iferror(vlookup(B24,StaffInformation!$F:$I,2,false),"") | E24: =iferror(vlookup(B24,Summary!$D:$V,19,false),) -> 0 | F24: 4 | Q24: 22 | R24: Tam.500 | T24: 0 | U24: =if(and($T24<0,$T24<=U$2),$A$2, ) | V24: =if(and($T24<0,$T24<=V$2),$A$2, ) | W24: =if(and($T24<0,$T24<=W$2),$A$2, ) | X24: =if(and($T24<0,$T24<=X$2),$A$2, ) | Y24: =if(and($T24<0,$T24<=Y$2),$A$2, ) | Z24: =if(and($T24<0,$T24<=Z$2),$A$2, ) | AA24: =if(and($T24<0,$T24<=AA$2),$A$2, ) | AB24: =if(T24=0,$A$3, ) -> x | AC24: =if(and(10>=$T24,$T24>=AC$2),$A$4,if(and(10<=$T24,$T24>=AC$2),$A$5, )) | AD24: =if(and(10>=$T24,$T24>=AD$2),$A$4,if(and(10<=$T24,$T24>=AD$2),$A$5, )) | AE24: =if(and(10>=$T24,$T24>=AE$2),$A$4,if(and(10<=$T24,$T24>=AE$2),$A$5, )) | AF24: =if(and(10>=$T24,$T24>=AF$2),$A$4,if(and(10<=$T24,$T24>=AF$2),$A$5, )) | AG24: =if(and(10>=$T24,$T24>=AG$2),$A$4,if(and(10<=$T24,$T24>=AG$2),$A$5, )) | AH24: =if(and(10>=$T24,$T24>=AH$2),$A$4,if(and(10<=$T24,$T24>=AH$2),$A$5, )) | AI24: =if(and(10>=$T24,$T24>=AI$2),$A$4,if(and(10<=$T24,$T24>=AI$2),$A$5, )) | AJ24: =if(and(10>=$T24,$T24>=AJ$2),$A$4,if(and(10<=$T24,$T24>=AJ$2),$A$5, )) | ... CR24: =if(and(10>=$T24,$T24>=CR$2),$A$4,if(and(10<=$T24,$T24>=CR$2),$A$5, ))
B25: =Summary!D52 -> GROUP - 500 - Tam | C25: Tam.500 | D25: =iferror(vlookup(B25,StaffInformation!$F:$I,2,false),"") | E25: =iferror(vlookup(B25,Summary!$D:$V,19,false),) -> 0 | F25: 5 | G25: Hieu.600 | I25: Completed target: | Q25: 23 | R25: Thao.500 | T25: 0 | U25: =if(and($T25<0,$T25<=U$2),$A$2, ) | V25: =if(and($T25<0,$T25<=V$2),$A$2, ) | W25: =if(and($T25<0,$T25<=W$2),$A$2, ) | X25: =if(and($T25<0,$T25<=X$2),$A$2, ) | Y25: =if(and($T25<0,$T25<=Y$2),$A$2, ) | Z25: =if(and($T25<0,$T25<=Z$2),$A$2, ) | AA25: =if(and($T25<0,$T25<=AA$2),$A$2, ) | AB25: =if(T25=0,$A$3, ) -> x | AC25: =if(and(10>=$T25,$T25>=AC$2),$A$4,if(and(10<=$T25,$T25>=AC$2),$A$5, )) | AD25: =if(and(10>=$T25,$T25>=AD$2),$A$4,if(and(10<=$T25,$T25>=AD$2),$A$5, )) | AE25: =if(and(10>=$T25,$T25>=AE$2),$A$4,if(and(10<=$T25,$T25>=AE$2),$A$5, )) | AF25: =if(and(10>=$T25,$T25>=AF$2),$A$4,if(and(10<=$T25,$T25>=AF$2),$A$5, )) | AG25: =if(and(10>=$T25,$T25>=AG$2),$A$4,if(and(10<=$T25,$T25>=AG$2),$A$5, )) | AH25: =if(and(10>=$T25,$T25>=AH$2),$A$4,if(and(10<=$T25,$T25>=AH$2),$A$5, )) | AI25: =if(and(10>=$T25,$T25>=AI$2),$A$4,if(and(10<=$T25,$T25>=AI$2),$A$5, )) | AJ25: =if(and(10>=$T25,$T25>=AJ$2),$A$4,if(and(10<=$T25,$T25>=AJ$2),$A$5, )) | ... CR25: =if(and(10>=$T25,$T25>=CR$2),$A$4,if(and(10<=$T25,$T25>=CR$2),$A$5, ))
B26: =Summary!D53 -> GROUP - 500 - Thao | C26: Thao.500 | D26: =iferror(vlookup(B26,'Copy of StaffInformation'!$F:$I,2,false),"") | E26: =iferror(vlookup(B26,Summary!$D:$V,19,false),) -> 0 | G26: ="complete"&$H$5&F21 -> completeHieu.6001 | H26: r | I26: =if(J26=$G$2,,"🏅") | J26: =vlookup(G26,StaffInformation!$C:$F,3,false) | Q26: 24 | R26: Quyen.500 | T26: 0 | U26: =if(and($T26<0,$T26<=U$2),$A$2, ) | V26: =if(and($T26<0,$T26<=V$2),$A$2, ) | W26: =if(and($T26<0,$T26<=W$2),$A$2, ) | X26: =if(and($T26<0,$T26<=X$2),$A$2, ) | Y26: =if(and($T26<0,$T26<=Y$2),$A$2, ) | Z26: =if(and($T26<0,$T26<=Z$2),$A$2, ) | AA26: =if(and($T26<0,$T26<=AA$2),$A$2, ) | AB26: =if(T26=0,$A$3, ) -> x | AC26: =if(and(10>=$T26,$T26>=AC$2),$A$4,if(and(10<=$T26,$T26>=AC$2),$A$5, )) | AD26: =if(and(10>=$T26,$T26>=AD$2),$A$4,if(and(10<=$T26,$T26>=AD$2),$A$5, )) | AE26: =if(and(10>=$T26,$T26>=AE$2),$A$4,if(and(10<=$T26,$T26>=AE$2),$A$5, )) | AF26: =if(and(10>=$T26,$T26>=AF$2),$A$4,if(and(10<=$T26,$T26>=AF$2),$A$5, )) | AG26: =if(and(10>=$T26,$T26>=AG$2),$A$4,if(and(10<=$T26,$T26>=AG$2),$A$5, )) | AH26: =if(and(10>=$T26,$T26>=AH$2),$A$4,if(and(10<=$T26,$T26>=AH$2),$A$5, )) | AI26: =if(and(10>=$T26,$T26>=AI$2),$A$4,if(and(10<=$T26,$T26>=AI$2),$A$5, )) | AJ26: =if(and(10>=$T26,$T26>=AJ$2),$A$4,if(and(10<=$T26,$T26>=AJ$2),$A$5, )) | ... CR26: =if(and(10>=$T26,$T26>=CR$2),$A$4,if(and(10<=$T26,$T26>=CR$2),$A$5, ))
B27: =Summary!D54 -> GROUP - 500 - Quyen | C27: Quyen.500 | D27: =iferror(vlookup(B27,StaffInformation!$F:$I,2,false),"") | E27: =iferror(vlookup(B27,Summary!$D:$V,19,false),) -> 0 | G27: ="complete"&$H$5&F22 -> completeHieu.6002 | H27: r | I27: =if(J27=$G$2,,"🏅") | J27: =vlookup(G27,StaffInformation!$C:$F,3,false) | Q27: 25 | R27: Hieu.100 | T27: 0 | U27: =if(and($T27<0,$T27<=U$2),$A$2, ) | V27: =if(and($T27<0,$T27<=V$2),$A$2, ) | W27: =if(and($T27<0,$T27<=W$2),$A$2, ) | X27: =if(and($T27<0,$T27<=X$2),$A$2, ) | Y27: =if(and($T27<0,$T27<=Y$2),$A$2, ) | Z27: =if(and($T27<0,$T27<=Z$2),$A$2, ) | AA27: =if(and($T27<0,$T27<=AA$2),$A$2, ) | AB27: =if(T27=0,$A$3, ) -> x | AC27: =if(and(10>=$T27,$T27>=AC$2),$A$4,if(and(10<=$T27,$T27>=AC$2),$A$5, )) | AD27: =if(and(10>=$T27,$T27>=AD$2),$A$4,if(and(10<=$T27,$T27>=AD$2),$A$5, )) | AE27: =if(and(10>=$T27,$T27>=AE$2),$A$4,if(and(10<=$T27,$T27>=AE$2),$A$5, )) | AF27: =if(and(10>=$T27,$T27>=AF$2),$A$4,if(and(10<=$T27,$T27>=AF$2),$A$5, )) | AG27: =if(and(10>=$T27,$T27>=AG$2),$A$4,if(and(10<=$T27,$T27>=AG$2),$A$5, )) | AH27: =if(and(10>=$T27,$T27>=AH$2),$A$4,if(and(10<=$T27,$T27>=AH$2),$A$5, )) | AI27: =if(and(10>=$T27,$T27>=AI$2),$A$4,if(and(10<=$T27,$T27>=AI$2),$A$5, )) | AJ27: =if(and(10>=$T27,$T27>=AJ$2),$A$4,if(and(10<=$T27,$T27>=AJ$2),$A$5, )) | ... CR27: =if(and(10>=$T27,$T27>=CR$2),$A$4,if(and(10<=$T27,$T27>=CR$2),$A$5, ))
B28: =Summary!D55 -> GROUP - 000-100 - Hieu | C28: Hieu.100 | D28: =iferror(vlookup(B28,StaffInformation!$F:$I,2,false),"") | E28: =iferror(vlookup(B28,Summary!$D:$V,19,false),) -> 0 | G28: ="complete"&$H$5&F23 -> completeHieu.6003 | H28: r | I28: =if(J28=$G$2,,"🏅") | J28: =vlookup(G28,StaffInformation!$C:$F,3,false) | U28: =if(and($T28<0,$T28<=U$2),$A$2, ) | V28: =if(and($T28<0,$T28<=V$2),$A$2, ) | W28: =if(and($T28<0,$T28<=W$2),$A$2, ) | X28: =if(and($T28<0,$T28<=X$2),$A$2, ) | Y28: =if(and($T28<0,$T28<=Y$2),$A$2, ) | Z28: =if(and($T28<0,$T28<=Z$2),$A$2, ) | AA28: =if(and($T28<0,$T28<=AA$2),$A$2, )
G29: ="complete"&$H$5&F24 -> completeHieu.6004 | H29: r | I29: =if(J29=$G$2,,"🏅") | J29: =vlookup(G29,StaffInformation!$C:$F,3,false) | U29: =if(and($T29<0,$T29<=U$2),$A$2, ) | V29: =if(and($T29<0,$T29<=V$2),$A$2, ) | W29: =if(and($T29<0,$T29<=W$2),$A$2, ) | X29: =if(and($T29<0,$T29<=X$2),$A$2, ) | Y29: =if(and($T29<0,$T29<=Y$2),$A$2, ) | Z29: =if(and($T29<0,$T29<=Z$2),$A$2, ) | AA29: =if(and($T29<0,$T29<=AA$2),$A$2, ) | AC29: =if(and(10>=$T29,$T29>=AC$2),$A$4,if(and(10<=$T29,$T29>=AC$2),$A$5, )) | AD29: =if(and(10>=$T29,$T29>=AD$2),$A$4,if(and(10<=$T29,$T29>=AD$2),$A$5, )) | AE29: =if(and(10>=$T29,$T29>=AE$2),$A$4,if(and(10<=$T29,$T29>=AE$2),$A$5, )) | AF29: =if(and(10>=$T29,$T29>=AF$2),$A$4,if(and(10<=$T29,$T29>=AF$2),$A$5, )) | AG29: =if(and(10>=$T29,$T29>=AG$2),$A$4,if(and(10<=$T29,$T29>=AG$2),$A$5, )) | AH29: =if(and(10>=$T29,$T29>=AH$2),$A$4,if(and(10<=$T29,$T29>=AH$2),$A$5, )) | AI29: =if(and(10>=$T29,$T29>=AI$2),$A$4,if(and(10<=$T29,$T29>=AI$2),$A$5, )) | AJ29: =if(and(10>=$T29,$T29>=AJ$2),$A$4,if(and(10<=$T29,$T29>=AJ$2),$A$5, )) | ... CR29: =if(and(10>=$T29,$T29>=CR$2),$A$4,if(and(10<=$T29,$T29>=CR$2),$A$5, ))
F30: 6 | G30: ="complete"&#REF!&F30 -> #REF! | I30: =if(#REF!=$G$2,,"🏅") -> #REF!
F31: 7 | G31: ="complete"&#REF!&F31 -> #REF! | I31: =if(#REF!=$G$2,,"🏅") -> #REF!
F32: 8 | G32: ="complete"&#REF!&F32 -> #REF! | I32: =if(#REF!=$G$2,,"🏅") -> #REF!
F33: 9 | G33: ="complete"&#REF!&F33 -> #REF! | I33: =if(#REF!=$G$2,,"🏅") -> #REF!
F34: 10 | G34: ="complete"&#REF!&F34 -> #REF! | I34: =if(#REF!=$G$2,,"🏅") -> #REF!
F35: 11 | G35: ="complete"&#REF!&F35 -> #REF! | I35: =if(#REF!=$G$2,,"🏅") -> #REF!
F36: 12 | G36: ="complete"&#REF!&F36 -> #REF! | I36: =if(#REF!=$G$2,,"🏅") -> #REF!
F37: 13 | G37: ="complete"&#REF!&F37 -> #REF! | I37: =if(#REF!=$G$2,,"🏅") -> #REF!
F38: 14 | G38: ="complete"&#REF!&F38 -> #REF! | I38: =if(#REF!=$G$2,,"🏅") -> #REF!
F39: 15 | G39: ="complete"&#REF!&F39 -> #REF! | I39: =if(#REF!=$G$2,,"🏅") -> #REF!
F40: 16 | G40: ="complete"&#REF!&F40 -> #REF! | I40: =if(#REF!=$G$2,,"🏅") -> #REF!
...

Sheet Summary
C25: - Automatically calculating -
M26: Total Penalty/ Bonus - Result - 결과 | V26: =AH62 -> 2026
C27: WARNING: Do NOT DELETE this row !!! | I27: =date($AH$62,1,1) -> 46023 | J27: =date($AH$62,2,1) -> 46054 | K27: =date($AH$62,3,1) -> 46082 | L27: =date($AH$62,4,1) -> 46113 | M27: =date($AH$62,5,1) -> 46143 | N27: =date($AH$62,6,1) -> 46174 | O27: =date($AH$62,7,1) -> 46204 | P27: =date($AH$62,8,1) -> 46235 | Q27: =date($AH$62,9,1) -> 46266 | R27: =date($AH$62,10,1) -> 46296 | S27: =date($AH$62,11,1) -> 46327 | T27: =date($AH$62,12,1) -> 46357
D28: Staff Code | E28: Staff - 인사 | G28: Email | H28: Position - 위치 | I28: =date($AH$62,2,1) -> 46054 | J28: =date($AH$62,3,1) -> 46082 | K28: =date($AH$62,4,1) -> 46113 | L28: =date($AH$62,5,1) -> 46143 | M28: =date($AH$62,6,1) -> 46174 | N28: =date($AH$62,7,1) -> 46204 | O28: =date($AH$62,8,1) -> 46235 | P28: =date($AH$62,9,1) -> 46266 | Q28: =date($AH$62,10,1) -> 46296 | R28: =date($AH$62,11,1) -> 46327 | S28: =date($AH$62,12,1) -> 46357 | T28: =date($AH$62+1,1,1) -> 46388
C29: VPA | D29: VPA - 600 - Hieu | E29: Hieu.600 | F29: Bui Trung | G29: hieubt@planadd.com | H29: Staff - 600 | I29: =sumifs(Boss!$D:$D,Boss!$B:$B,$D29,Boss!$A:$A,">="&I$27,Boss!$A:$A,"<="&I$28)+sumifs(VPA.Director!$D:$D,VPA.Director!$B:$B,$D29,VPA.Director!$A:$A,">="&I$27,VPA.Director!$A:$A,"<="&I$28)+sumifs(ADC.Director!$D:$D,ADC.Director!$B:$B,$D29,ADC.Director!$A:$A,">="&I$27,ADC.Director!$A:$A,"<="&I$28)+sumifs('000'!$D:$D,'000'!$B:$B,$D29,'000'!$A:$A,">="&I$27,'000'!$A:$A,"<="&I$28)+sumifs('500'!$D:$D,'500'!$B:$B,$D29,'500'!$A:$A,">="&I$27,'500'!$A:$A,"<="&I$28)+sumifs('300'!$D:$D,'300'!$B:$B,$D29,'300'!$A:$A,">="&I$27,'300'!$A:$A,"<="&I$28)+sumifs('600.VPA'!$D:$D,'600.VPA'!$B:$B,$D29,'600.VPA'!$A:$A,">="&I$27,'600.VPA'!$A:$A,"<="&I$28) -> 0 | J29: =sumifs(Boss!$D:$D,Boss!$B:$B,$D29,Boss!$A:$A,">="&J$27,Boss!$A:$A,"<="&J$28)+sumifs(VPA.Director!$D:$D,VPA.Director!$B:$B,$D29,VPA.Director!$A:$A,">="&J$27,VPA.Director!$A:$A,"<="&J$28)+sumifs(ADC.Director!$D:$D,ADC.Director!$B:$B,$D29,ADC.Director!$A:$A,">="&J$27,ADC.Director!$A:$A,"<="&J$28)+sumifs('000'!$D:$D,'000'!$B:$B,$D29,'000'!$A:$A,">="&J$27,'000'!$A:$A,"<="&J$28)+sumifs('500'!$D:$D,'500'!$B:$B,$D29,'500'!$A:$A,">="&J$27,'500'!$A:$A,"<="&J$28)+sumifs('300'!$D:$D,'300'!$B:$B,$D29,'300'!$A:$A,">="&J$27,'300'!$A:$A,"<="&J$28)+sumifs('600.VPA'!$D:$D,'600.VPA'!$B:$B,$D29,'600.VPA'!$A:$A,">="&J$27,'600.VPA'!$A:$A,"<="&J$28) -> 0 | K29: =sumifs(Boss!$D:$D,Boss!$B:$B,$D29,Boss!$A:$A,">="&K$27,Boss!$A:$A,"<="&K$28)+sumifs(VPA.Director!$D:$D,VPA.Director!$B:$B,$D29,VPA.Director!$A:$A,">="&K$27,VPA.Director!$A:$A,"<="&K$28)+sumifs(ADC.Director!$D:$D,ADC.Director!$B:$B,$D29,ADC.Director!$A:$A,">="&K$27,ADC.Director!$A:$A,"<="&K$28)+sumifs('000'!$D:$D,'000'!$B:$B,$D29,'000'!$A:$A,">="&K$27,'000'!$A:$A,"<="&K$28)+sumifs('500'!$D:$D,'500'!$B:$B,$D29,'500'!$A:$A,">="&K$27,'500'!$A:$A,"<="&K$28)+sumifs('300'!$D:$D,'300'!$B:$B,$D29,'300'!$A:$A,">="&K$27,'300'!$A:$A,"<="&K$28)+sumifs('600.VPA'!$D:$D,'600.VPA'!$B:$B,$D29,'600.VPA'!$A:$A,">="&K$27,'600.VPA'!$A:$A,"<="&K$28) -> 0 | L29: =sumifs(Boss!$D:$D,Boss!$B:$B,$D29,Boss!$A:$A,">="&L$27,Boss!$A:$A,"<="&L$28)+sumifs(VPA.Director!$D:$D,VPA.Director!$B:$B,$D29,VPA.Director!$A:$A,">="&L$27,VPA.Director!$A:$A,"<="&L$28)+sumifs(ADC.Director!$D:$D,ADC.Director!$B:$B,$D29,ADC.Director!$A:$A,">="&L$27,ADC.Director!$A:$A,"<="&L$28)+sumifs('000'!$D:$D,'000'!$B:$B,$D29,'000'!$A:$A,">="&L$27,'000'!$A:$A,"<="&L$28)+sumifs('500'!$D:$D,'500'!$B:$B,$D29,'500'!$A:$A,">="&L$27,'500'!$A:$A,"<="&L$28)+sumifs('300'!$D:$D,'300'!$B:$B,$D29,'300'!$A:$A,">="&L$27,'300'!$A:$A,"<="&L$28)+sumifs('600.VPA'!$D:$D,'600.VPA'!$B:$B,$D29,'600.VPA'!$A:$A,">="&L$27,'600.VPA'!$A:$A,"<="&L$28) -> 0 | M29: =sumifs(Boss!$D:$D,Boss!$B:$B,$D29,Boss!$A:$A,">="&M$27,Boss!$A:$A,"<="&M$28)+sumifs(VPA.Director!$D:$D,VPA.Director!$B:$B,$D29,VPA.Director!$A:$A,">="&M$27,VPA.Director!$A:$A,"<="&M$28)+sumifs(ADC.Director!$D:$D,ADC.Director!$B:$B,$D29,ADC.Director!$A:$A,">="&M$27,ADC.Director!$A:$A,"<="&M$28)+sumifs('000'!$D:$D,'000'!$B:$B,$D29,'000'!$A:$A,">="&M$27,'000'!$A:$A,"<="&M$28)+sumifs('500'!$D:$D,'500'!$B:$B,$D29,'500'!$A:$A,">="&M$27,'500'!$A:$A,"<="&M$28)+sumifs('300'!$D:$D,'300'!$B:$B,$D29,'300'!$A:$A,">="&M$27,'300'!$A:$A,"<="&M$28)+sumifs('600.VPA'!$D:$D,'600.VPA'!$B:$B,$D29,'600.VPA'!$A:$A,">="&M$27,'600.VPA'!$A:$A,"<="&M$28) -> 0 | N29: =sumifs(Boss!$D:$D,Boss!$B:$B,$D29,Boss!$A:$A,">="&N$27,Boss!$A:$A,"<="&N$28)+sumifs(VPA.Director!$D:$D,VPA.Director!$B:$B,$D29,VPA.Director!$A:$A,">="&N$27,VPA.Director!$A:$A,"<="&N$28)+sumifs(ADC.Director!$D:$D,ADC.Director!$B:$B,$D29,ADC.Director!$A:$A,">="&N$27,ADC.Director!$A:$A,"<="&N$28)+sumifs('000'!$D:$D,'000'!$B:$B,$D29,'000'!$A:$A,">="&N$27,'000'!$A:$A,"<="&N$28)+sumifs('500'!$D:$D,'500'!$B:$B,$D29,'500'!$A:$A,">="&N$27,'500'!$A:$A,"<="&N$28)+sumifs('300'!$D:$D,'300'!$B:$B,$D29,'300'!$A:$A,">="&N$27,'300'!$A:$A,"<="&N$28)+sumifs('600.VPA'!$D:$D,'600.VPA'!$B:$B,$D29,'600.VPA'!$A:$A,">="&N$27,'600.VPA'!$A:$A,"<="&N$28) -> 0 | O29: =sumifs(Boss!$D:$D,Boss!$B:$B,$D29,Boss!$A:$A,">="&O$27,Boss!$A:$A,"<="&O$28)+sumifs(VPA.Director!$D:$D,VPA.Director!$B:$B,$D29,VPA.Director!$A:$A,">="&O$27,VPA.Director!$A:$A,"<="&O$28)+sumifs(ADC.Director!$D:$D,ADC.Director!$B:$B,$D29,ADC.Director!$A:$A,">="&O$27,ADC.Director!$A:$A,"<="&O$28)+sumifs('000'!$D:$D,'000'!$B:$B,$D29,'000'!$A:$A,">="&O$27,'000'!$A:$A,"<="&O$28)+sumifs('500'!$D:$D,'500'!$B:$B,$D29,'500'!$A:$A,">="&O$27,'500'!$A:$A,"<="&O$28)+sumifs('300'!$D:$D,'300'!$B:$B,$D29,'300'!$A:$A,">="&O$27,'300'!$A:$A,"<="&O$28)+sumifs('600.VPA'!$D:$D,'600.VPA'!$B:$B,$D29,'600.VPA'!$A:$A,">="&O$27,'600.VPA'!$A:$A,"<="&O$28) -> 0 | P29: =sumifs(Boss!$D:$D,Boss!$B:$B,$D29,Boss!$A:$A,">="&P$27,Boss!$A:$A,"<="&P$28)+sumifs(VPA.Director!$D:$D,VPA.Director!$B:$B,$D29,VPA.Director!$A:$A,">="&P$27,VPA.Director!$A:$A,"<="&P$28)+sumifs(ADC.Director!$D:$D,ADC.Director!$B:$B,$D29,ADC.Director!$A:$A,">="&P$27,ADC.Director!$A:$A,"<="&P$28)+sumifs('000'!$D:$D,'000'!$B:$B,$D29,'000'!$A:$A,">="&P$27,'000'!$A:$A,"<="&P$28)+sumifs('500'!$D:$D,'500'!$B:$B,$D29,'500'!$A:$A,">="&P$27,'500'!$A:$A,"<="&P$28)+sumifs('300'!$D:$D,'300'!$B:$B,$D29,'300'!$A:$A,">="&P$27,'300'!$A:$A,"<="&P$28)+sumifs('600.VPA'!$D:$D,'600.VPA'!$B:$B,$D29,'600.VPA'!$A:$A,">="&P$27,'600.VPA'!$A:$A,"<="&P$28) -> 0 | ... T29: =sumifs(Boss!$D:$D,Boss!$B:$B,$D29,Boss!$A:$A,">="&T$27,Boss!$A:$A,"<="&T$28)+sumifs(VPA.Director!$D:$D,VPA.Director!$B:$B,$D29,VPA.Director!$A:$A,">="&T$27,VPA.Director!$A:$A,"<="&T$28)+sumifs(ADC.Director!$D:$D,ADC.Director!$B:$B,$D29,ADC.Director!$A:$A,">="&T$27,ADC.Director!$A:$A,"<="&T$28)+sumifs('000'!$D:$D,'000'!$B:$B,$D29,'000'!$A:$A,">="&T$27,'000'!$A:$A,"<="&T$28)+sumifs('500'!$D:$D,'500'!$B:$B,$D29,'500'!$A:$A,">="&T$27,'500'!$A:$A,"<="&T$28)+sumifs('300'!$D:$D,'300'!$B:$B,$D29,'300'!$A:$A,">="&T$27,'300'!$A:$A,"<="&T$28)+sumifs('600.VPA'!$D:$D,'600.VPA'!$B:$B,$D29,'600.VPA'!$A:$A,">="&T$27,'600.VPA'!$A:$A,"<="&T$28) -> 0 | V29: =sum(I29:T29) -> 0
D30: VPA - 600 - Dat | E30: Dat.600 | F30: Tran Tien | G30: dattt@planadd.com | H30: Staff - 600 | I30: =sumifs(Boss!$D:$D,Boss!$B:$B,$D30,Boss!$A:$A,">="&I$27,Boss!$A:$A,"<="&I$28)+sumifs(VPA.Director!$D:$D,VPA.Director!$B:$B,$D30,VPA.Director!$A:$A,">="&I$27,VPA.Director!$A:$A,"<="&I$28)+sumifs(ADC.Director!$D:$D,ADC.Director!$B:$B,$D30,ADC.Director!$A:$A,">="&I$27,ADC.Director!$A:$A,"<="&I$28)+sumifs('000'!$D:$D,'000'!$B:$B,$D30,'000'!$A:$A,">="&I$27,'000'!$A:$A,"<="&I$28)+sumifs('500'!$D:$D,'500'!$B:$B,$D30,'500'!$A:$A,">="&I$27,'500'!$A:$A,"<="&I$28)+sumifs('300'!$D:$D,'300'!$B:$B,$D30,'300'!$A:$A,">="&I$27,'300'!$A:$A,"<="&I$28)+sumifs('600.VPA'!$D:$D,'600.VPA'!$B:$B,$D30,'600.VPA'!$A:$A,">="&I$27,'600.VPA'!$A:$A,"<="&I$28) -> 0 | J30: =sumifs(Boss!$D:$D,Boss!$B:$B,$D30,Boss!$A:$A,">="&J$27,Boss!$A:$A,"<="&J$28)+sumifs(VPA.Director!$D:$D,VPA.Director!$B:$B,$D30,VPA.Director!$A:$A,">="&J$27,VPA.Director!$A:$A,"<="&J$28)+sumifs(ADC.Director!$D:$D,ADC.Director!$B:$B,$D30,ADC.Director!$A:$A,">="&J$27,ADC.Director!$A:$A,"<="&J$28)+sumifs('000'!$D:$D,'000'!$B:$B,$D30,'000'!$A:$A,">="&J$27,'000'!$A:$A,"<="&J$28)+sumifs('500'!$D:$D,'500'!$B:$B,$D30,'500'!$A:$A,">="&J$27,'500'!$A:$A,"<="&J$28)+sumifs('300'!$D:$D,'300'!$B:$B,$D30,'300'!$A:$A,">="&J$27,'300'!$A:$A,"<="&J$28)+sumifs('600.VPA'!$D:$D,'600.VPA'!$B:$B,$D30,'600.VPA'!$A:$A,">="&J$27,'600.VPA'!$A:$A,"<="&J$28) -> 0 | K30: =sumifs(Boss!$D:$D,Boss!$B:$B,$D30,Boss!$A:$A,">="&K$27,Boss!$A:$A,"<="&K$28)+sumifs(VPA.Director!$D:$D,VPA.Director!$B:$B,$D30,VPA.Director!$A:$A,">="&K$27,VPA.Director!$A:$A,"<="&K$28)+sumifs(ADC.Director!$D:$D,ADC.Director!$B:$B,$D30,ADC.Director!$A:$A,">="&K$27,ADC.Director!$A:$A,"<="&K$28)+sumifs('000'!$D:$D,'000'!$B:$B,$D30,'000'!$A:$A,">="&K$27,'000'!$A:$A,"<="&K$28)+sumifs('500'!$D:$D,'500'!$B:$B,$D30,'500'!$A:$A,">="&K$27,'500'!$A:$A,"<="&K$28)+sumifs('300'!$D:$D,'300'!$B:$B,$D30,'300'!$A:$A,">="&K$27,'300'!$A:$A,"<="&K$28)+sumifs('600.VPA'!$D:$D,'600.VPA'!$B:$B,$D30,'600.VPA'!$A:$A,">="&K$27,'600.VPA'!$A:$A,"<="&K$28) -> 0 | L30: =sumifs(Boss!$D:$D,Boss!$B:$B,$D30,Boss!$A:$A,">="&L$27,Boss!$A:$A,"<="&L$28)+sumifs(VPA.Director!$D:$D,VPA.Director!$B:$B,$D30,VPA.Director!$A:$A,">="&L$27,VPA.Director!$A:$A,"<="&L$28)+sumifs(ADC.Director!$D:$D,ADC.Director!$B:$B,$D30,ADC.Director!$A:$A,">="&L$27,ADC.Director!$A:$A,"<="&L$28)+sumifs('000'!$D:$D,'000'!$B:$B,$D30,'000'!$A:$A,">="&L$27,'000'!$A:$A,"<="&L$28)+sumifs('500'!$D:$D,'500'!$B:$B,$D30,'500'!$A:$A,">="&L$27,'500'!$A:$A,"<="&L$28)+sumifs('300'!$D:$D,'300'!$B:$B,$D30,'300'!$A:$A,">="&L$27,'300'!$A:$A,"<="&L$28)+sumifs('600.VPA'!$D:$D,'600.VPA'!$B:$B,$D30,'600.VPA'!$A:$A,">="&L$27,'600.VPA'!$A:$A,"<="&L$28) -> 0 | M30: =sumifs(Boss!$D:$D,Boss!$B:$B,$D30,Boss!$A:$A,">="&M$27,Boss!$A:$A,"<="&M$28)+sumifs(VPA.Director!$D:$D,VPA.Director!$B:$B,$D30,VPA.Director!$A:$A,">="&M$27,VPA.Director!$A:$A,"<="&M$28)+sumifs(ADC.Director!$D:$D,ADC.Director!$B:$B,$D30,ADC.Director!$A:$A,">="&M$27,ADC.Director!$A:$A,"<="&M$28)+sumifs('000'!$D:$D,'000'!$B:$B,$D30,'000'!$A:$A,">="&M$27,'000'!$A:$A,"<="&M$28)+sumifs('500'!$D:$D,'500'!$B:$B,$D30,'500'!$A:$A,">="&M$27,'500'!$A:$A,"<="&M$28)+sumifs('300'!$D:$D,'300'!$B:$B,$D30,'300'!$A:$A,">="&M$27,'300'!$A:$A,"<="&M$28)+sumifs('600.VPA'!$D:$D,'600.VPA'!$B:$B,$D30,'600.VPA'!$A:$A,">="&M$27,'600.VPA'!$A:$A,"<="&M$28) -> 0 | N30: =sumifs(Boss!$D:$D,Boss!$B:$B,$D30,Boss!$A:$A,">="&N$27,Boss!$A:$A,"<="&N$28)+sumifs(VPA.Director!$D:$D,VPA.Director!$B:$B,$D30,VPA.Director!$A:$A,">="&N$27,VPA.Director!$A:$A,"<="&N$28)+sumifs(ADC.Director!$D:$D,ADC.Director!$B:$B,$D30,ADC.Director!$A:$A,">="&N$27,ADC.Director!$A:$A,"<="&N$28)+sumifs('000'!$D:$D,'000'!$B:$B,$D30,'000'!$A:$A,">="&N$27,'000'!$A:$A,"<="&N$28)+sumifs('500'!$D:$D,'500'!$B:$B,$D30,'500'!$A:$A,">="&N$27,'500'!$A:$A,"<="&N$28)+sumifs('300'!$D:$D,'300'!$B:$B,$D30,'300'!$A:$A,">="&N$27,'300'!$A:$A,"<="&N$28)+sumifs('600.VPA'!$D:$D,'600.VPA'!$B:$B,$D30,'600.VPA'!$A:$A,">="&N$27,'600.VPA'!$A:$A,"<="&N$28) -> 0 | O30: =sumifs(Boss!$D:$D,Boss!$B:$B,$D30,Boss!$A:$A,">="&O$27,Boss!$A:$A,"<="&O$28)+sumifs(VPA.Director!$D:$D,VPA.Director!$B:$B,$D30,VPA.Director!$A:$A,">="&O$27,VPA.Director!$A:$A,"<="&O$28)+sumifs(ADC.Director!$D:$D,ADC.Director!$B:$B,$D30,ADC.Director!$A:$A,">="&O$27,ADC.Director!$A:$A,"<="&O$28)+sumifs('000'!$D:$D,'000'!$B:$B,$D30,'000'!$A:$A,">="&O$27,'000'!$A:$A,"<="&O$28)+sumifs('500'!$D:$D,'500'!$B:$B,$D30,'500'!$A:$A,">="&O$27,'500'!$A:$A,"<="&O$28)+sumifs('300'!$D:$D,'300'!$B:$B,$D30,'300'!$A:$A,">="&O$27,'300'!$A:$A,"<="&O$28)+sumifs('600.VPA'!$D:$D,'600.VPA'!$B:$B,$D30,'600.VPA'!$A:$A,">="&O$27,'600.VPA'!$A:$A,"<="&O$28) -> 0 | P30: =sumifs(Boss!$D:$D,Boss!$B:$B,$D30,Boss!$A:$A,">="&P$27,Boss!$A:$A,"<="&P$28)+sumifs(VPA.Director!$D:$D,VPA.Director!$B:$B,$D30,VPA.Director!$A:$A,">="&P$27,VPA.Director!$A:$A,"<="&P$28)+sumifs(ADC.Director!$D:$D,ADC.Director!$B:$B,$D30,ADC.Director!$A:$A,">="&P$27,ADC.Director!$A:$A,"<="&P$28)+sumifs('000'!$D:$D,'000'!$B:$B,$D30,'000'!$A:$A,">="&P$27,'000'!$A:$A,"<="&P$28)+sumifs('500'!$D:$D,'500'!$B:$B,$D30,'500'!$A:$A,">="&P$27,'500'!$A:$A,"<="&P$28)+sumifs('300'!$D:$D,'300'!$B:$B,$D30,'300'!$A:$A,">="&P$27,'300'!$A:$A,"<="&P$28)+sumifs('600.VPA'!$D:$D,'600.VPA'!$B:$B,$D30,'600.VPA'!$A:$A,">="&P$27,'600.VPA'!$A:$A,"<="&P$28) -> 0 | ... T30: =sumifs(Boss!$D:$D,Boss!$B:$B,$D30,Boss!$A:$A,">="&T$27,Boss!$A:$A,"<="&T$28)+sumifs(VPA.Director!$D:$D,VPA.Director!$B:$B,$D30,VPA.Director!$A:$A,">="&T$27,VPA.Director!$A:$A,"<="&T$28)+sumifs(ADC.Director!$D:$D,ADC.Director!$B:$B,$D30,ADC.Director!$A:$A,">="&T$27,ADC.Director!$A:$A,"<="&T$28)+sumifs('000'!$D:$D,'000'!$B:$B,$D30,'000'!$A:$A,">="&T$27,'000'!$A:$A,"<="&T$28)+sumifs('500'!$D:$D,'500'!$B:$B,$D30,'500'!$A:$A,">="&T$27,'500'!$A:$A,"<="&T$28)+sumifs('300'!$D:$D,'300'!$B:$B,$D30,'300'!$A:$A,">="&T$27,'300'!$A:$A,"<="&T$28)+sumifs('600.VPA'!$D:$D,'600.VPA'!$B:$B,$D30,'600.VPA'!$A:$A,">="&T$27,'600.VPA'!$A:$A,"<="&T$28) -> 0 | V30: =sum(I30:T30) -> 0
D31: VPA - 600 - Trang | E31: Trang.600 | F31: Nguyen Thi Thu | G31: ntttrang@planadd.com | H31: Vice Team Leader | I31: =sumifs(Boss!$D:$D,Boss!$B:$B,$D31,Boss!$A:$A,">="&I$27,Boss!$A:$A,"<="&I$28)+sumifs(VPA.Director!$D:$D,VPA.Director!$B:$B,$D31,VPA.Director!$A:$A,">="&I$27,VPA.Director!$A:$A,"<="&I$28)+sumifs(ADC.Director!$D:$D,ADC.Director!$B:$B,$D31,ADC.Director!$A:$A,">="&I$27,ADC.Director!$A:$A,"<="&I$28)+sumifs('000'!$D:$D,'000'!$B:$B,$D31,'000'!$A:$A,">="&I$27,'000'!$A:$A,"<="&I$28)+sumifs('500'!$D:$D,'500'!$B:$B,$D31,'500'!$A:$A,">="&I$27,'500'!$A:$A,"<="&I$28)+sumifs('300'!$D:$D,'300'!$B:$B,$D31,'300'!$A:$A,">="&I$27,'300'!$A:$A,"<="&I$28)+sumifs('600.VPA'!$D:$D,'600.VPA'!$B:$B,$D31,'600.VPA'!$A:$A,">="&I$27,'600.VPA'!$A:$A,"<="&I$28) -> 0 | J31: =sumifs(Boss!$D:$D,Boss!$B:$B,$D31,Boss!$A:$A,">="&J$27,Boss!$A:$A,"<="&J$28)+sumifs(VPA.Director!$D:$D,VPA.Director!$B:$B,$D31,VPA.Director!$A:$A,">="&J$27,VPA.Director!$A:$A,"<="&J$28)+sumifs(ADC.Director!$D:$D,ADC.Director!$B:$B,$D31,ADC.Director!$A:$A,">="&J$27,ADC.Director!$A:$A,"<="&J$28)+sumifs('000'!$D:$D,'000'!$B:$B,$D31,'000'!$A:$A,">="&J$27,'000'!$A:$A,"<="&J$28)+sumifs('500'!$D:$D,'500'!$B:$B,$D31,'500'!$A:$A,">="&J$27,'500'!$A:$A,"<="&J$28)+sumifs('300'!$D:$D,'300'!$B:$B,$D31,'300'!$A:$A,">="&J$27,'300'!$A:$A,"<="&J$28)+sumifs('600.VPA'!$D:$D,'600.VPA'!$B:$B,$D31,'600.VPA'!$A:$A,">="&J$27,'600.VPA'!$A:$A,"<="&J$28) -> 0 | K31: =sumifs(Boss!$D:$D,Boss!$B:$B,$D31,Boss!$A:$A,">="&K$27,Boss!$A:$A,"<="&K$28)+sumifs(VPA.Director!$D:$D,VPA.Director!$B:$B,$D31,VPA.Director!$A:$A,">="&K$27,VPA.Director!$A:$A,"<="&K$28)+sumifs(ADC.Director!$D:$D,ADC.Director!$B:$B,$D31,ADC.Director!$A:$A,">="&K$27,ADC.Director!$A:$A,"<="&K$28)+sumifs('000'!$D:$D,'000'!$B:$B,$D31,'000'!$A:$A,">="&K$27,'000'!$A:$A,"<="&K$28)+sumifs('500'!$D:$D,'500'!$B:$B,$D31,'500'!$A:$A,">="&K$27,'500'!$A:$A,"<="&K$28)+sumifs('300'!$D:$D,'300'!$B:$B,$D31,'300'!$A:$A,">="&K$27,'300'!$A:$A,"<="&K$28)+sumifs('600.VPA'!$D:$D,'600.VPA'!$B:$B,$D31,'600.VPA'!$A:$A,">="&K$27,'600.VPA'!$A:$A,"<="&K$28) -> 0 | L31: =sumifs(Boss!$D:$D,Boss!$B:$B,$D31,Boss!$A:$A,">="&L$27,Boss!$A:$A,"<="&L$28)+sumifs(VPA.Director!$D:$D,VPA.Director!$B:$B,$D31,VPA.Director!$A:$A,">="&L$27,VPA.Director!$A:$A,"<="&L$28)+sumifs(ADC.Director!$D:$D,ADC.Director!$B:$B,$D31,ADC.Director!$A:$A,">="&L$27,ADC.Director!$A:$A,"<="&L$28)+sumifs('000'!$D:$D,'000'!$B:$B,$D31,'000'!$A:$A,">="&L$27,'000'!$A:$A,"<="&L$28)+sumifs('500'!$D:$D,'500'!$B:$B,$D31,'500'!$A:$A,">="&L$27,'500'!$A:$A,"<="&L$28)+sumifs('300'!$D:$D,'300'!$B:$B,$D31,'300'!$A:$A,">="&L$27,'300'!$A:$A,"<="&L$28)+sumifs('600.VPA'!$D:$D,'600.VPA'!$B:$B,$D31,'600.VPA'!$A:$A,">="&L$27,'600.VPA'!$A:$A,"<="&L$28) -> 0 | M31: =sumifs(Boss!$D:$D,Boss!$B:$B,$D31,Boss!$A:$A,">="&M$27,Boss!$A:$A,"<="&M$28)+sumifs(VPA.Director!$D:$D,VPA.Director!$B:$B,$D31,VPA.Director!$A:$A,">="&M$27,VPA.Director!$A:$A,"<="&M$28)+sumifs(ADC.Director!$D:$D,ADC.Director!$B:$B,$D31,ADC.Director!$A:$A,">="&M$27,ADC.Director!$A:$A,"<="&M$28)+sumifs('000'!$D:$D,'000'!$B:$B,$D31,'000'!$A:$A,">="&M$27,'000'!$A:$A,"<="&M$28)+sumifs('500'!$D:$D,'500'!$B:$B,$D31,'500'!$A:$A,">="&M$27,'500'!$A:$A,"<="&M$28)+sumifs('300'!$D:$D,'300'!$B:$B,$D31,'300'!$A:$A,">="&M$27,'300'!$A:$A,"<="&M$28)+sumifs('600.VPA'!$D:$D,'600.VPA'!$B:$B,$D31,'600.VPA'!$A:$A,">="&M$27,'600.VPA'!$A:$A,"<="&M$28) -> 0 | N31: =sumifs(Boss!$D:$D,Boss!$B:$B,$D31,Boss!$A:$A,">="&N$27,Boss!$A:$A,"<="&N$28)+sumifs(VPA.Director!$D:$D,VPA.Director!$B:$B,$D31,VPA.Director!$A:$A,">="&N$27,VPA.Director!$A:$A,"<="&N$28)+sumifs(ADC.Director!$D:$D,ADC.Director!$B:$B,$D31,ADC.Director!$A:$A,">="&N$27,ADC.Director!$A:$A,"<="&N$28)+sumifs('000'!$D:$D,'000'!$B:$B,$D31,'000'!$A:$A,">="&N$27,'000'!$A:$A,"<="&N$28)+sumifs('500'!$D:$D,'500'!$B:$B,$D31,'500'!$A:$A,">="&N$27,'500'!$A:$A,"<="&N$28)+sumifs('300'!$D:$D,'300'!$B:$B,$D31,'300'!$A:$A,">="&N$27,'300'!$A:$A,"<="&N$28)+sumifs('600.VPA'!$D:$D,'600.VPA'!$B:$B,$D31,'600.VPA'!$A:$A,">="&N$27,'600.VPA'!$A:$A,"<="&N$28) -> 0 | O31: =sumifs(Boss!$D:$D,Boss!$B:$B,$D31,Boss!$A:$A,">="&O$27,Boss!$A:$A,"<="&O$28)+sumifs(VPA.Director!$D:$D,VPA.Director!$B:$B,$D31,VPA.Director!$A:$A,">="&O$27,VPA.Director!$A:$A,"<="&O$28)+sumifs(ADC.Director!$D:$D,ADC.Director!$B:$B,$D31,ADC.Director!$A:$A,">="&O$27,ADC.Director!$A:$A,"<="&O$28)+sumifs('000'!$D:$D,'000'!$B:$B,$D31,'000'!$A:$A,">="&O$27,'000'!$A:$A,"<="&O$28)+sumifs('500'!$D:$D,'500'!$B:$B,$D31,'500'!$A:$A,">="&O$27,'500'!$A:$A,"<="&O$28)+sumifs('300'!$D:$D,'300'!$B:$B,$D31,'300'!$A:$A,">="&O$27,'300'!$A:$A,"<="&O$28)+sumifs('600.VPA'!$D:$D,'600.VPA'!$B:$B,$D31,'600.VPA'!$A:$A,">="&O$27,'600.VPA'!$A:$A,"<="&O$28) -> 0 | P31: =sumifs(Boss!$D:$D,Boss!$B:$B,$D31,Boss!$A:$A,">="&P$27,Boss!$A:$A,"<="&P$28)+sumifs(VPA.Director!$D:$D,VPA.Director!$B:$B,$D31,VPA.Director!$A:$A,">="&P$27,VPA.Director!$A:$A,"<="&P$28)+sumifs(ADC.Director!$D:$D,ADC.Director!$B:$B,$D31,ADC.Director!$A:$A,">="&P$27,ADC.Director!$A:$A,"<="&P$28)+sumifs('000'!$D:$D,'000'!$B:$B,$D31,'000'!$A:$A,">="&P$27,'000'!$A:$A,"<="&P$28)+sumifs('500'!$D:$D,'500'!$B:$B,$D31,'500'!$A:$A,">="&P$27,'500'!$A:$A,"<="&P$28)+sumifs('300'!$D:$D,'300'!$B:$B,$D31,'300'!$A:$A,">="&P$27,'300'!$A:$A,"<="&P$28)+sumifs('600.VPA'!$D:$D,'600.VPA'!$B:$B,$D31,'600.VPA'!$A:$A,">="&P$27,'600.VPA'!$A:$A,"<="&P$28) -> 0 | ... T31: =sumifs(Boss!$D:$D,Boss!$B:$B,$D31,Boss!$A:$A,">="&T$27,Boss!$A:$A,"<="&T$28)+sumifs(VPA.Director!$D:$D,VPA.Director!$B:$B,$D31,VPA.Director!$A:$A,">="&T$27,VPA.Director!$A:$A,"<="&T$28)+sumifs(ADC.Director!$D:$D,ADC.Director!$B:$B,$D31,ADC.Director!$A:$A,">="&T$27,ADC.Director!$A:$A,"<="&T$28)+sumifs('000'!$D:$D,'000'!$B:$B,$D31,'000'!$A:$A,">="&T$27,'000'!$A:$A,"<="&T$28)+sumifs('500'!$D:$D,'500'!$B:$B,$D31,'500'!$A:$A,">="&T$27,'500'!$A:$A,"<="&T$28)+sumifs('300'!$D:$D,'300'!$B:$B,$D31,'300'!$A:$A,">="&T$27,'300'!$A:$A,"<="&T$28)+sumifs('600.VPA'!$D:$D,'600.VPA'!$B:$B,$D31,'600.VPA'!$A:$A,">="&T$27,'600.VPA'!$A:$A,"<="&T$28) -> 0 | V31: =sum(I31:T31) -> 0
